<sdf version='1.7'>
  <model name='testrig'>
    <link name='base_link'>
      <inertial>
        <pose>0 0 0.50025 0 -0 0</pose>
        <mass>2001</mass>
        <inertia>
          <ixx>1283.25</ixx>
          <ixy>0</ixy>
          <ixz>0</ixz>
          <iyy>3.24988</iyy>
          <iyz>0</iyz>
          <izz>1283</izz>
        </inertia>
      </inertial>
      <collision name='base_link_fixed_joint_lump__support_left_collision'>
        <pose>0 0.8 0.5 0 -0 0</pose>
        <geometry>
          <box>
            <size>0.5 0.25 1</size>
          </box>
        </geometry>
        <surface>
          <contact>
            <ode/>
          </contact>
          <friction>
            <ode/>
          </friction>
        </surface>
      </collision>
      <collision name='base_link_fixed_joint_lump__support_right_collision_1'>
        <pose>0 -0.8 0.5 0 -0 0</pose>
        <geometry>
          <box>
            <size>0.5 0.25 1</size>
          </box>
        </geometry>
        <surface>
          <contact>
            <ode/>
          </contact>
          <friction>
            <ode/>
          </friction>
        </surface>
      </collision>
      <visual name='base_link_fixed_joint_lump__gantry_visual'>
        <pose>0 0 1 0 -0 0</pose>
        <geometry>
          <box>
            <size>0.05 1.6 0.05</size>
          </box>
        </geometry>
        <material>
          <script>
            <name>Gazebo/White</name>
            <uri>file://media/materials/scripts/gazebo.material</uri>
          </script>
        </material>
      </visual>
      <visual name='base_link_fixed_joint_lump__support_left_visual_1'>
        <pose>0 0.8 0.5 0 -0 0</pose>
        <geometry>
          <box>
            <size>0.5 0.25 1</size>
          </box>
        </geometry>
        <material>
          <script>
            <name>Gazebo/Red</name>
            <uri>file://media/materials/scripts/gazebo.material</uri>
          </script>
        </material>
      </visual>
      <visual name='base_link_fixed_joint_lump__support_right_visual_2'>
        <pose>0 -0.8 0.5 0 -0 0</pose>
        <geometry>
          <box>
            <size>0.5 0.25 1</size>
          </box>
        </geometry>
        <material>
          <script>
            <name>Gazebo/Red</name>
            <uri>file://media/materials/scripts/gazebo.material</uri>
          </script>
        </material>
      </visual>
    </link>
    <joint name='gantry_to_vertical_rail' type='prismatic'>
      <pose relative_to='base_link'>0 0 1 0 -0 0</pose>
      <parent>base_link</parent>
      <child>vertical_rail</child>
      <axis>
        <xyz>0 0 1</xyz>
        <limit>
          <lower>-0.5</lower>
          <upper>0</upper>
          <effort>100</effort>
          <velocity>10</velocity>
        </limit>
        <dynamics>
          <spring_reference>0</spring_reference>
          <spring_stiffness>0</spring_stiffness>
        </dynamics>
      </axis>
    </joint>
    <link name='vertical_rail'>
      <pose relative_to='gantry_to_vertical_rail'>0 0 0 0 -0 0</pose>
      <inertial>
        <pose>0 0 0 0 -0 0</pose>
        <mass>30</mass>
        <inertia>
          <ixx>1</ixx>
          <ixy>0</ixy>
          <ixz>0</ixz>
          <iyy>1</iyy>
          <iyz>0</iyz>
          <izz>1</izz>
        </inertia>
      </inertial>
      <visual name='vertical_rail_visual'>
        <pose>0 0 0 0 -0 0</pose>
        <geometry>
          <box>
            <size>0.1 0.1 0.1</size>
          </box>
        </geometry>
        <material>
          <script>
            <name>Gazebo/White</name>
            <uri>file://media/materials/scripts/gazebo.material</uri>
          </script>
        </material>
      </visual>
    </link>
  </model>
</sdf>
