<?xml version="1.0"?>
<robot xmlns:xacro="http://www.ros.org/wiki/xacro" name="jetleg_testrig">

    <link name="base_link">
    </link>

    <!-- Include the JetLeg -->
    <xacro:include filename="$(find jetleg_description)/urdf/jetleg.xacro"/> 

    <!-- Create two JetLegs -->
    <xacro:jetleg identifier="">
    </xacro:jetleg>

    <!-- Include components -->
    <xacro:include filename="$(find jetleg_description)/urdf/components/imu.xacro" />
    <xacro:jetleg_imu />

    <joint name="base_link_to_jetleg" type="revolute">
        <parent link="base_link" />
        <child link="thigh" />
        <axis xyz="0 1 0"/>
        <origin xyz="0 0 0" rpy="0 0 0" />
        <limit effort="100" lower="0.0" upper="0.5" velocity="10"/>
    </joint>

    <!-- Define the additional joints of the robot -->
</robot>
