<?xml version="1.0" ?>
<!-- =================================================================================== -->
<!-- |    This document was autogenerated by xacro from testrig_odrive.xacro           | -->
<!-- |    EDITING THIS FILE BY HAND IS NOT RECOMMENDED                                 | -->
<!-- =================================================================================== -->
<robot name="jetleg_testrig_odrive">
  <material name="white">
    <color rgba="1 1 1 1"/>
  </material>
  <material name="red">
    <color rgba="1 0 0 1"/>
  </material>
  <material name="red_transluscent">
    <color rgba="1 0 0 0.25"/>
  </material>
  <material name="white_transluscent">
    <color rgba="1 1 1 0.25"/>
  </material>
  <link name="base_link">
    </link>
  <link name="gantry">
    <visual>
      <geometry>
        <box size="0.05 1.6 0.05"/>
      </geometry>
      <material name="white_transluscent"/>
    </visual>
    <collision>
      <geometry>
        <box size="0.05 1.6 0.05"/>
      </geometry>
    </collision>
    <inertial>
      <mass value="100"/>
      <inertia ixx="10" ixy="0" ixz="0" iyy="10" iyz="0" izz="10"/>
    </inertial>
  </link>
  <joint name="base_to_gantry" type="fixed">
    <origin rpy="0 0 0" xyz="0 0 1"/>
    <parent link="base_link"/>
    <child link="gantry"/>
  </joint>
  <link name="support_left">
    <visual>
      <geometry>
        <box size="0.5 0.25 1"/>
      </geometry>
      <material name="red_transluscent"/>
    </visual>
    <collision>
      <geometry>
        <box size="0.5 0.25 1"/>
      </geometry>
    </collision>
    <inertial>
      <mass value="1000"/>
      <inertia ixx="100" ixy="0" ixz="0" iyy="100" iyz="0" izz="100"/>
    </inertial>
  </link>
  <joint name="gantry_to_support_left" type="fixed">
    <parent link="gantry"/>
    <child link="support_left"/>
    <origin xyz="0 0.8 -0.5"/>
  </joint>
  <link name="support_right">
    <visual>
      <geometry>
        <box size="0.5 0.25 1"/>
      </geometry>
      <material name="red_transluscent"/>
    </visual>
    <collision>
      <geometry>
        <box size="0.5 0.25 1"/>
      </geometry>
    </collision>
    <inertial>
      <mass value="1000"/>
      <inertia ixx="100" ixy="0" ixz="0" iyy="100" iyz="0" izz="100"/>
    </inertial>
  </link>
  <joint name="gantry_to_support_right" type="fixed">
    <parent link="gantry"/>
    <child link="support_right"/>
    <origin xyz="0 -0.8 -0.5"/>
  </joint>
  <joint name="gantry_to_mount" type="revolute">
    <origin rpy="0 0 0" xyz="0 0 0"/>
    <parent link="gantry"/>
    <child link="mount"/>
    <limit effort="100" lower="-0.6981317007977318" upper="0.6981317007977318" velocity="10"/>
    <axis xyz="0 1 0"/>
  </joint>
  <link name="mount">
    <visual>
      <geometry>
        <cylinder length="0.24" radius="0.08"/>
      </geometry>
      <material name="white_transluscent"/>
    </visual>
    <collision>
      <geometry>
        <cylinder length="0.24" radius="0.08"/>
      </geometry>
    </collision>
    <inertial>
      <mass value="100"/>
      <inertia ixx="10" ixy="0" ixz="0" iyy="10" iyz="0" izz="10"/>
    </inertial>
  </link>
  <link name="thigh">
    <visual>
      <geometry>
        <cylinder length="0.3" radius="0.06"/>
      </geometry>
      <material name="white"/>
    </visual>
    <collision>
      <geometry>
        <cylinder length="0.3" radius="0.06"/>
      </geometry>
    </collision>
    <inertial>
      <mass value="10"/>
      <inertia ixx="1" ixy="0" ixz="0" iyy="1" iyz="0" izz="1"/>
    </inertial>
  </link>
  <link name="shank">
    <visual>
      <geometry>
        <cylinder length="0.3" radius="0.06"/>
      </geometry>
      <material name="white"/>
      <origin rpy="0 0 0" xyz="0 0 -0.175"/>
    </visual>
    <collision>
      <geometry>
        <cylinder length="0.3" radius="0.06"/>
      </geometry>
      <origin rpy="0 0 0" xyz="0 0 -0.175"/>
    </collision>
    <inertial>
      <mass value="10"/>
      <inertia ixx="1" ixy="0" ixz="0" iyy="1" iyz="0" izz="1"/>
      <origin rpy="0 0 0" xyz="0 0 -0.175"/>
    </inertial>
  </link>
  <joint name="knee_joint" type="revolute">
    <origin rpy="0 0 0" xyz="0 0 -0.175"/>
    <parent link="thigh"/>
    <child link="shank"/>
    <axis xyz="0 1 0"/>
    <limit effort="100" lower="0.0" upper="1.5" velocity="10"/>
  </joint>
  <link name="foot">
    <visual>
      <geometry>
        <box size="0.3 0.1 0.05"/>
      </geometry>
      <material name="white"/>
      <origin xyz="0.09999999999999999 0 -0.05"/>
    </visual>
    <collision>
      <geometry>
        <box size="0.3 0.1 0.05"/>
      </geometry>
      <origin xyz="0.09999999999999999 0 -0.05"/>
    </collision>
    <inertial>
      <mass value="10"/>
      <inertia ixx="1" ixy="0" ixz="0" iyy="1" iyz="0" izz="1"/>
      <origin xyz="0.09999999999999999 0 -0.05"/>
    </inertial>
  </link>
  <joint name="ankle_joint" type="revolute">
    <origin rpy="0 0 0" xyz="0 0 -0.35000000000000003"/>
    <parent link="shank"/>
    <child link="foot"/>
    <axis xyz="0 1 0"/>
    <limit effort="100" lower="-0.1" upper="0.5" velocity="10"/>
  </joint>
  <joint name="mount_to_jetleg" type="fixed">
    <parent link="mount"/>
    <child link="thigh"/>
    <origin rpy="0 0 0" xyz="0 0 -0.15"/>
  </joint>
  <ros2_control name="jetleg_ros2_control" type="system">
    <hardware>
      <plugin>odrive_hardware_interface/ODriveHardwareInterface</plugin>
    </hardware>
    <sensor name="odrv0">
      <param name="serial_number">000000000000</param>
    </sensor>
    <joint name="knee_joint">
      <param name="serial_number">000000000000</param>
      <param name="axis">0</param>
      <param name="enable_watchdog">1</param>
      <param name="watchdog_timeout">0.1</param>
    </joint>
  </ros2_control>
</robot>
